Workbook

Sheet AllPayPoints
A1: Classification | B1: Pay Point | C1: Existing | D1: 43722 | E1: 44088 | F1: 44269 | G1: 45169 | H1: 45365 | I1: 45729 | J1: 46093
A2: APS 1 | B2: 1 | C2: 43119 | D2: 44628 | E2: 45297 | F2: 45750 | G2: 48022 | H2: 52000 | I2: 54516 | J2: 57497
A3: APS 1 | B3: 2 | C3: 44286 | D3: 45836 | E3: 46524 | F3: 46989 | G3: 49323 | H3: 52000 | I3: 54516 | J3: 57688
A4: APS 1 | B4: 3 | C4: 47982 | D4: 49661 | E4: 50406 | F4: 50910 | G4: – | H4: 53438 | I4: 55576 | J4: 59649
A5: APS 1 | B5: 4 | C5: – | D5: – | E5: – | F5: – | G5: – | H5: – | I5: 57787 | J5: 60946
A6: APS 2 | B6: 1 | C6: 49786 | D6: 51529 | E6: 52302 | F6: 52825 | G6: 55448 | H6: 57666 | I6: 59857 | J6: 62775
A7: APS 2 | B7: 2 | C7: 51079 | D7: 52867 | E7: 53660 | F7: 54197 | G7: 56888 | H7: 59164 | I7: 61412 | J7: 63500
A8: APS 2 | B8: 3 | C8: 54564 | D8: 56474 | E8: 57321 | F8: 57894 | G8: 60769 | H8: 63200 | I8: 65602 | J8: 67832
A9: APS 2 | B9: 4 | C9: 54671 | D9: 56584 | E9: 57433 | F9: 58007 | G9: – | H9: – | I9: – | J9: 68425
A10: APS 3 | B10: 1 | C10: 55174 | D10: 57105 | E10: 57962 | F10: 58542 | G10: 61449 | H10: 63907 | I10: 66823 | J10: 70477
A11: APS 3 | B11: 2 | C11: 56574 | D11: 58554 | E11: 59432 | F11: 60026 | G11: 63006 | H11: 65526 | I11: 68016 | J11: 70477
A12: APS 3 | B12: 3 | C12: 60428 | D12: 62543 | E12: 63481 | F12: 64116 | G12: 67299 | H12: 69991 | I12: 72651 | J12: 75121
A13: APS 3 | B13: 4 | C13: – | D13: – | E13: – | F13: – | G13: – | H13: – | I13: 72837 | J13: 76820
A14: APS 3 (TO L2) | B14: 1 | C14: 55174 | D14: 57105 | E14: 57962 | F14: 58542 | G14: 61449 | H14: 63907 | I14: 66823 | J14: 70477
A15: APS 3 (TO L2) | B15: 2 | C15: 56574 | D15: 58554 | E15: 59432 | F15: 60026 | G15: 63006 | H15: 65526 | I15: 68016 | J15: 70477
A16: APS 3 (TO L2) | B16: 3 | C16: 60428 | D16: 62543 | E16: 63481 | F16: 64116 | G16: 67299 | H16: 69991 | I16: 72651 | J16: 75121
A17: APS 3 (TO L2) | B17: 4 (TO2) | C17: 60551 | D17: 62670 | E17: 63610 | F17: 64246 | G17: 67436 | H17: 70133 | I17: 72798 | J17: 75273
A18: APS 3 (TO L2) | B18: 5 (TO2) | C18: 61034 | D18: 63170 | E18: 64118 | F18: 64759 | G18: 67974 | H18: 70693 | I18: 73379 | J18: 75874
A19: APS 3 (TO L2) | B19: 6 (TO2) | C19: 64574 | D19: 66834 | E19: 67837 | F19: 68515 | G19: 71917 | H19: 74794 | I19: 77636 | J19: 80276
A20: APS 4 | B20: 1 | C20: 61845 | D20: 64010 | E20: 64970 | F20: 65620 | G20: 68878 | H20: 71633 | I20: 75022 | J20: 79125
A21: APS 4 | B21: 2 | C21: 63452 | D21: 65673 | E21: 66658 | F21: 67325 | G21: 70667 | H21: 73494 | I21: 76287 | J21: 79125
A22: APS 4 | B22: 3 | C22: 67820 | D22: 70194 | E22: 71247 | F22: 71959 | G22: 75532 | H22: 78553 | I22: 81538 | J22: 84310
A23: APS 4 | B23: 4 | C23: – | D23: – | E23: – | F23: – | G23: – | H23: – | I23: 81775 | J23: 86246
A24: APS 5 | B24: 1 | C24: 68944 | D24: 71357 | E24: 72427 | F24: 73151 | G24: 76783 | H24: 80341 | I24: 84228 | J24: 88834
A25: APS 5 | B25: 2 | C25: 70886 | D25: 73367 | E25: 74468 | F25: 75213 | G25: 78947 | H25: 82105 | I25: 85225 | J25: 88834
A26: APS 5 | B26: 3 | C26: 75139 | D26: 77769 | E26: 78936 | F26: 79725 | G26: 83683 | H26: 87030 | I26: 90337 | J26: 93408
A27: APS 5 | B27: 4 | C27: – | D27: – | E27: – | F27: – | G27: – | H27: 87572 | I27: 91809 | J27: 94931
A28: APS 5 | B28: 5 | C28: – | D28: – | E28: – | F28: – | G28: – | H28: – | I28: – | J28: 96829
A29: APS 6 | B29: 1 | C29: 76025 | D29: 78686 | E29: 79866 | F29: 80665 | G29: 84670 | H29: 90199 | I29: 94563 | J29: 99734
A30: APS 6 | B30: 2 | C30: 79848 | D30: 82643 | E30: 83883 | F30: 84722 | G30: 88929 | H30: 92486 | I30: 96000 | J30: 99734
A31: APS 6 | B31: 3 | C31: 86438 | D31: 89463 | E31: 90805 | F31: 91713 | G31: 96267 | H31: 100118 | I31: 103922 | J31: 107455
A32: APS 6 | B32: 4 | C32: – | D32: – | E32: – | F32: – | G32: – | H32: 101022 | I32: 105910 | J32: 109511
A33: APS 6 | B33: 5 | C33: – | D33: – | E33: – | F33: – | G33: – | H33: – | I33: – | J33: 111701
A34: EL1 | B34: 1 | C34: 92560 | D34: 95800 | E34: 97237 | F34: 98209 | G34: 103085 | H34: 110115 | I34: 115443 | J34: 121755
A35: EL1 | B35: 2 | C35: 96255 | D35: 99624 | E35: 101118 | F35: 102129 | G35: 107200 | H35: 111489 | I35: 115725 | J35: 121755
A36: EL1 | B36: 3 | C36: 104260 | D36: 107909 | E36: 109528 | F36: 110623 | G36: 116115 | H36: 120760 | I36: 125348 | J36: 129611
A37: EL1 | B37: 4 | C37: – | D37: – | E37: – | F37: – | G37: – | H37: – | I37: 125832 | J37: 132713
A38: EL2 Lower | B38: 1 | C38: 112622 | D38: 116564 | E38: 118312 | F38: 119495 | G38: 125428 | H38: 130445 | I38: 135402 | J38: 140675
A39: EL2 Lower | B39: 2 | C39: 116828 | D39: 120917 | E39: 122731 | F39: 123958 | G39: 130113 | H39: 135318 | I39: 140460 | J39: 145236
A40: EL2 Lower | B40: 3 | C40: 126488 | D40: 130915 | E40: 132879 | F40: 134208 | G40: 140871 | H40: 146506 | I40: 152073 | J40: 157243
...

Sheet MaxPayPoints
A1: Classification | B1: 43466 | C1: 43722 | D1: 44088 | E1: 44269 | F1: 45169 | G1: 45365 | H1: 45729 | I1: 46093
A2: APS 1 | B2: 47982 | C2: 49661 | D2: 50406 | E2: 50910 | F2: 49323 | G2: 53438 | H2: 57787 | I2: 60946
A3: APS 2 | B3: 54671 | C3: 56584 | D3: 57433 | E3: 58007 | F3: 60769 | G3: 63200 | H3: 65602 | I3: 68425
A4: APS 3 | B4: 60428 | C4: 62543 | D4: 63481 | E4: 64116 | F4: 67299 | G4: 69991 | H4: 72837 | I4: 76820
A5: APS 4 | B5: 67820 | C5: 70194 | D5: 71247 | E5: 71959 | F5: 75532 | G5: 78553 | H5: 81775 | I5: 86246
A6: APS 5 | B6: 75139 | C6: 77769 | D6: 78936 | E6: 79725 | F6: 83683 | G6: 87572 | H6: 91809 | I6: 96829
A7: APS 6 | B7: 86438 | C7: 89463 | D7: 90805 | E7: 91713 | F7: 96267 | G7: 101022 | H7: 105910 | I7: 111701
A8: EL1 | B8: 104260 | C8: 107909 | D8: 109528 | E8: 110623 | F8: 116115 | G8: 120760 | H8: 125832 | I8: 132713
A9: EL2 Lower | B9: 126488 | C9: 130915 | D9: 132879 | E9: 134208 | F9: 140871 | G9: 146506 | H9: 152073 | I9: 157243
A10: EL2 Upper | B10: 137458 | C10: 142269 | D10: 144403 | E10: 145847 | F10: 153089 | G10: 159213 | H10: 165263 | I10: 170882

Sheet MaxPayPoints Transposed
A1: Classification | B1: APS 1 | C1: APS 2 | D1: APS 3 | E1: APS 4 | F1: APS 5 | G1: APS 6 | H1: EL1 | I1: EL2 Lower | J1: EL2 Upper
A2: 43466 | B2: 47982 | C2: 54671 | D2: 60428 | E2: 67820 | F2: 75139 | G2: 86438 | H2: 104260 | I2: 126488 | J2: 137458
A3: 43722 | B3: 49661 | C3: 56584 | D3: 62543 | E3: 70194 | F3: 77769 | G3: 89463 | H3: 107909 | I3: 130915 | J3: 142269
A4: 44088 | B4: 50406 | C4: 57433 | D4: 63481 | E4: 71247 | F4: 78936 | G4: 90805 | H4: 109528 | I4: 132879 | J4: 144403
A5: 44269 | B5: 50910 | C5: 58007 | D5: 64116 | E5: 71959 | F5: 79725 | G5: 91713 | H5: 110623 | I5: 134208 | J5: 145847
A6: 45169 | B6: 49323 | C6: 60769 | D6: 67299 | E6: 75532 | F6: 83683 | G6: 96267 | H6: 116115 | I6: 140871 | J6: 153089
A7: 45365 | B7: 53438 | C7: 63200 | D7: 69991 | E7: 78553 | F7: 87572 | G7: 101022 | H7: 120760 | I7: 146506 | J7: 159213
A8: 45729 | B8: 57787 | C8: 65602 | D8: 72837 | E8: 81775 | F8: 91809 | G8: 105910 | H8: 125832 | I8: 152073 | J8: 165263
A9: 46093 | B9: 60946 | C9: 68425 | D9: 76820 | E9: 86246 | F9: 96829 | G9: 111701 | H9: 132713 | I9: 157243 | J9: 170882

Sheet CPI
A1: Date | B1: Percentage Change from Previous Period ; All groups CPI ; Australia ;
A2: 43800 | B2: 0.7
A3: 43891 | B3: 0.4
A4: 43983 | B4: -1.9
A5: 44075 | B5: 1.5
A6: 44166 | B6: 0.9
A7: 44256 | B7: 0.6
A8: 44348 | B8: 0.7
A9: 44440 | B9: 0.8
A10: 44531 | B10: 1.3
A11: 44621 | B11: 2.2
A12: 44713 | B12: 1.8
A13: 44805 | B13: 1.8
... A26: 45992 | B26: 0.6

Sheet SLCI
A1: Date | B1: Percentage Change from Previous Period ; Employee households ; All groups ;
A2: 38504 | B2: 1
A3: 38596 | B3: 1.1
A4: 38687 | B4: 0.4
A5: 38777 | B5: 1.1
A6: 38869 | B6: 1.8
A7: 38961 | B7: 1.2
A8: 39052 | B8: 0.1
A9: 39142 | B9: 0.4
A10: 39234 | B10: 1.3
A11: 39326 | B11: 0.9
A12: 39417 | B12: 1
A13: 39508 | B13: 1.8
... A85: 46082 | B85: 1.4

Sheet Fortnightly Pay
A1: Pay Date | B1: Fortnightly CPI | C1: Fortnightly SLCI | D1: APS3 Fortnightly Pay | E1: APS4 Fortnightly Pay | F1: APS5 Fortnightly Pay | G1: APS6 Fortnightly Pay | H1: EL1 Fortnightly Pay | I1: EL2 L Fortnightly Pay | J1: EL2 U Fortnightly Pay
A2: 43839 | B2: =_xlfn.XLOOKUP(A2, CPI!A:A, CPI!B:B, "missing",-1,1)/6.5 -> 0.10769231 | C2: =_xlfn.XLOOKUP(A2, SLCI!A:A, SLCI!B:B, "missing", -1)/6.5 -> 0.046153846 | D2: =_xlfn.XLOOKUP(A2, 'MaxPayPoints Transposed'!A:A, 'MaxPayPoints Transposed'!D:D, "missing", -1)/26 -> 2405.5 | E2: =_xlfn.XLOOKUP(A2, 'MaxPayPoints Transposed'!A:A, 'MaxPayPoints Transposed'!E:E, "missing", -1)/26 -> 2699.7692 | F2: =_xlfn.XLOOKUP(A2, 'MaxPayPoints Transposed'!A:A, 'MaxPayPoints Transposed'!F:F, "missing", -1)/26 -> 2991.1154 | G2: =_xlfn.XLOOKUP(A2, 'MaxPayPoints Transposed'!A:A, 'MaxPayPoints Transposed'!G:G, "missing", -1)/26 -> 3440.8846 | H2: =_xlfn.XLOOKUP(A2, 'MaxPayPoints Transposed'!A:A, 'MaxPayPoints Transposed'!H:H, "missing", -1)/26 -> 4150.3462 | I2: =_xlfn.XLOOKUP(A2, 'MaxPayPoints Transposed'!A:A, 'MaxPayPoints Transposed'!I:I, "missing", -1)/26 -> 5035.1923 | J2: =_xlfn.XLOOKUP(A2, 'MaxPayPoints Transposed'!A:A, 'MaxPayPoints Transposed'!J:J, "missing", -1)/26 -> 5471.8846
A3: 43853 | B3: =_xlfn.XLOOKUP(A3, CPI!A:A, CPI!B:B, "missing",-1,1)/6.5 -> 0.10769231 | C3: =_xlfn.XLOOKUP(A3, SLCI!A:A, SLCI!B:B, "missing", -1)/6.5 -> 0.046153846 | D3: =_xlfn.XLOOKUP(A3, 'MaxPayPoints Transposed'!A:A, 'MaxPayPoints Transposed'!D:D, "missing", -1)/26 -> 2405.5 | E3: =_xlfn.XLOOKUP(A3, 'MaxPayPoints Transposed'!A:A, 'MaxPayPoints Transposed'!E:E, "missing", -1)/26 -> 2699.7692 | F3: =_xlfn.XLOOKUP(A3, 'MaxPayPoints Transposed'!A:A, 'MaxPayPoints Transposed'!F:F, "missing", -1)/26 -> 2991.1154 | G3: =_xlfn.XLOOKUP(A3, 'MaxPayPoints Transposed'!A:A, 'MaxPayPoints Transposed'!G:G, "missing", -1)/26 -> 3440.8846 | H3: =_xlfn.XLOOKUP(A3, 'MaxPayPoints Transposed'!A:A, 'MaxPayPoints Transposed'!H:H, "missing", -1)/26 -> 4150.3462 | I3: =_xlfn.XLOOKUP(A3, 'MaxPayPoints Transposed'!A:A, 'MaxPayPoints Transposed'!I:I, "missing", -1)/26 -> 5035.1923 | J3: =_xlfn.XLOOKUP(A3, 'MaxPayPoints Transposed'!A:A, 'MaxPayPoints Transposed'!J:J, "missing", -1)/26 -> 5471.8846
A4: 43867 | B4: =_xlfn.XLOOKUP(A4, CPI!A:A, CPI!B:B, "missing",-1,1)/6.5 -> 0.10769231 | C4: =_xlfn.XLOOKUP(A4, SLCI!A:A, SLCI!B:B, "missing", -1)/6.5 -> 0.046153846 | D4: =_xlfn.XLOOKUP(A4, 'MaxPayPoints Transposed'!A:A, 'MaxPayPoints Transposed'!D:D, "missing", -1)/26 -> 2405.5 | E4: =_xlfn.XLOOKUP(A4, 'MaxPayPoints Transposed'!A:A, 'MaxPayPoints Transposed'!E:E, "missing", -1)/26 -> 2699.7692 | F4: =_xlfn.XLOOKUP(A4, 'MaxPayPoints Transposed'!A:A, 'MaxPayPoints Transposed'!F:F, "missing", -1)/26 -> 2991.1154 | G4: =_xlfn.XLOOKUP(A4, 'MaxPayPoints Transposed'!A:A, 'MaxPayPoints Transposed'!G:G, "missing", -1)/26 -> 3440.8846 | H4: =_xlfn.XLOOKUP(A4, 'MaxPayPoints Transposed'!A:A, 'MaxPayPoints Transposed'!H:H, "missing", -1)/26 -> 4150.3462 | I4: =_xlfn.XLOOKUP(A4, 'MaxPayPoints Transposed'!A:A, 'MaxPayPoints Transposed'!I:I, "missing", -1)/26 -> 5035.1923 | J4: =_xlfn.XLOOKUP(A4, 'MaxPayPoints Transposed'!A:A, 'MaxPayPoints Transposed'!J:J, "missing", -1)/26 -> 5471.8846
A5: 43881 | B5: =_xlfn.XLOOKUP(A5, CPI!A:A, CPI!B:B, "missing",-1,1)/6.5 -> 0.10769231 | C5: =_xlfn.XLOOKUP(A5, SLCI!A:A, SLCI!B:B, "missing", -1)/6.5 -> 0.046153846 | D5: =_xlfn.XLOOKUP(A5, 'MaxPayPoints Transposed'!A:A, 'MaxPayPoints Transposed'!D:D, "missing", -1)/26 -> 2405.5 | E5: =_xlfn.XLOOKUP(A5, 'MaxPayPoints Transposed'!A:A, 'MaxPayPoints Transposed'!E:E, "missing", -1)/26 -> 2699.7692 | F5: =_xlfn.XLOOKUP(A5, 'MaxPayPoints Transposed'!A:A, 'MaxPayPoints Transposed'!F:F, "missing", -1)/26 -> 2991.1154 | G5: =_xlfn.XLOOKUP(A5, 'MaxPayPoints Transposed'!A:A, 'MaxPayPoints Transposed'!G:G, "missing", -1)/26 -> 3440.8846 | H5: =_xlfn.XLOOKUP(A5, 'MaxPayPoints Transposed'!A:A, 'MaxPayPoints Transposed'!H:H, "missing", -1)/26 -> 4150.3462 | I5: =_xlfn.XLOOKUP(A5, 'MaxPayPoints Transposed'!A:A, 'MaxPayPoints Transposed'!I:I, "missing", -1)/26 -> 5035.1923 | J5: =_xlfn.XLOOKUP(A5, 'MaxPayPoints Transposed'!A:A, 'MaxPayPoints Transposed'!J:J, "missing", -1)/26 -> 5471.8846
A6: 43895 | B6: =_xlfn.XLOOKUP(A6, CPI!A:A, CPI!B:B, "missing",-1,1)/6.5 -> 0.061538462 | C6: =_xlfn.XLOOKUP(A6, SLCI!A:A, SLCI!B:B, "missing", -1)/6.5 -> 0.030769231 | D6: =_xlfn.XLOOKUP(A6, 'MaxPayPoints Transposed'!A:A, 'MaxPayPoints Transposed'!D:D, "missing", -1)/26 -> 2405.5 | E6: =_xlfn.XLOOKUP(A6, 'MaxPayPoints Transposed'!A:A, 'MaxPayPoints Transposed'!E:E, "missing", -1)/26 -> 2699.7692 | F6: =_xlfn.XLOOKUP(A6, 'MaxPayPoints Transposed'!A:A, 'MaxPayPoints Transposed'!F:F, "missing", -1)/26 -> 2991.1154 | G6: =_xlfn.XLOOKUP(A6, 'MaxPayPoints Transposed'!A:A, 'MaxPayPoints Transposed'!G:G, "missing", -1)/26 -> 3440.8846 | H6: =_xlfn.XLOOKUP(A6, 'MaxPayPoints Transposed'!A:A, 'MaxPayPoints Transposed'!H:H, "missing", -1)/26 -> 4150.3462 | I6: =_xlfn.XLOOKUP(A6, 'MaxPayPoints Transposed'!A:A, 'MaxPayPoints Transposed'!I:I, "missing", -1)/26 -> 5035.1923 | J6: =_xlfn.XLOOKUP(A6, 'MaxPayPoints Transposed'!A:A, 'MaxPayPoints Transposed'!J:J, "missing", -1)/26 -> 5471.8846
A7: 43909 | B7: =_xlfn.XLOOKUP(A7, CPI!A:A, CPI!B:B, "missing",-1,1)/6.5 -> 0.061538462 | C7: =_xlfn.XLOOKUP(A7, SLCI!A:A, SLCI!B:B, "missing", -1)/6.5 -> 0.030769231 | D7: =_xlfn.XLOOKUP(A7, 'MaxPayPoints Transposed'!A:A, 'MaxPayPoints Transposed'!D:D, "missing", -1)/26 -> 2405.5 | E7: =_xlfn.XLOOKUP(A7, 'MaxPayPoints Transposed'!A:A, 'MaxPayPoints Transposed'!E:E, "missing", -1)/26 -> 2699.7692 | F7: =_xlfn.XLOOKUP(A7, 'MaxPayPoints Transposed'!A:A, 'MaxPayPoints Transposed'!F:F, "missing", -1)/26 -> 2991.1154 | G7: =_xlfn.XLOOKUP(A7, 'MaxPayPoints Transposed'!A:A, 'MaxPayPoints Transposed'!G:G, "missing", -1)/26 -> 3440.8846 | H7: =_xlfn.XLOOKUP(A7, 'MaxPayPoints Transposed'!A:A, 'MaxPayPoints Transposed'!H:H, "missing", -1)/26 -> 4150.3462 | I7: =_xlfn.XLOOKUP(A7, 'MaxPayPoints Transposed'!A:A, 'MaxPayPoints Transposed'!I:I, "missing", -1)/26 -> 5035.1923 | J7: =_xlfn.XLOOKUP(A7, 'MaxPayPoints Transposed'!A:A, 'MaxPayPoints Transposed'!J:J, "missing", -1)/26 -> 5471.8846
A8: 43923 | B8: =_xlfn.XLOOKUP(A8, CPI!A:A, CPI!B:B, "missing",-1,1)/6.5 -> 0.061538462 | C8: =_xlfn.XLOOKUP(A8, SLCI!A:A, SLCI!B:B, "missing", -1)/6.5 -> 0.030769231 | D8: =_xlfn.XLOOKUP(A8, 'MaxPayPoints Transposed'!A:A, 'MaxPayPoints Transposed'!D:D, "missing", -1)/26 -> 2405.5 | E8: =_xlfn.XLOOKUP(A8, 'MaxPayPoints Transposed'!A:A, 'MaxPayPoints Transposed'!E:E, "missing", -1)/26 -> 2699.7692 | F8: =_xlfn.XLOOKUP(A8, 'MaxPayPoints Transposed'!A:A, 'MaxPayPoints Transposed'!F:F, "missing", -1)/26 -> 2991.1154 | G8: =_xlfn.XLOOKUP(A8, 'MaxPayPoints Transposed'!A:A, 'MaxPayPoints Transposed'!G:G, "missing", -1)/26 -> 3440.8846 | H8: =_xlfn.XLOOKUP(A8, 'MaxPayPoints Transposed'!A:A, 'MaxPayPoints Transposed'!H:H, "missing", -1)/26 -> 4150.3462 | I8: =_xlfn.XLOOKUP(A8, 'MaxPayPoints Transposed'!A:A, 'MaxPayPoints Transposed'!I:I, "missing", -1)/26 -> 5035.1923 | J8: =_xlfn.XLOOKUP(A8, 'MaxPayPoints Transposed'!A:A, 'MaxPayPoints Transposed'!J:J, "missing", -1)/26 -> 5471.8846
A9: 43937 | B9: =_xlfn.XLOOKUP(A9, CPI!A:A, CPI!B:B, "missing",-1,1)/6.5 -> 0.061538462 | C9: =_xlfn.XLOOKUP(A9, SLCI!A:A, SLCI!B:B, "missing", -1)/6.5 -> 0.030769231 | D9: =_xlfn.XLOOKUP(A9, 'MaxPayPoints Transposed'!A:A, 'MaxPayPoints Transposed'!D:D, "missing", -1)/26 -> 2405.5 | E9: =_xlfn.XLOOKUP(A9, 'MaxPayPoints Transposed'!A:A, 'MaxPayPoints Transposed'!E:E, "missing", -1)/26 -> 2699.7692 | F9: =_xlfn.XLOOKUP(A9, 'MaxPayPoints Transposed'!A:A, 'MaxPayPoints Transposed'!F:F, "missing", -1)/26 -> 2991.1154 | G9: =_xlfn.XLOOKUP(A9, 'MaxPayPoints Transposed'!A:A, 'MaxPayPoints Transposed'!G:G, "missing", -1)/26 -> 3440.8846 | H9: =_xlfn.XLOOKUP(A9, 'MaxPayPoints Transposed'!A:A, 'MaxPayPoints Transposed'!H:H, "missing", -1)/26 -> 4150.3462 | I9: =_xlfn.XLOOKUP(A9, 'MaxPayPoints Transposed'!A:A, 'MaxPayPoints Transposed'!I:I, "missing", -1)/26 -> 5035.1923 | J9: =_xlfn.XLOOKUP(A9, 'MaxPayPoints Transposed'!A:A, 'MaxPayPoints Transposed'!J:J, "missing", -1)/26 -> 5471.8846
A10: 43951 | B10: =_xlfn.XLOOKUP(A10, CPI!A:A, CPI!B:B, "missing",-1,1)/6.5 -> 0.061538462 | C10: =_xlfn.XLOOKUP(A10, SLCI!A:A, SLCI!B:B, "missing", -1)/6.5 -> 0.030769231 | D10: =_xlfn.XLOOKUP(A10, 'MaxPayPoints Transposed'!A:A, 'MaxPayPoints Transposed'!D:D, "missing", -1)/26 -> 2405.5 | E10: =_xlfn.XLOOKUP(A10, 'MaxPayPoints Transposed'!A:A, 'MaxPayPoints Transposed'!E:E, "missing", -1)/26 -> 2699.7692 | F10: =_xlfn.XLOOKUP(A10, 'MaxPayPoints Transposed'!A:A, 'MaxPayPoints Transposed'!F:F, "missing", -1)/26 -> 2991.1154 | G10: =_xlfn.XLOOKUP(A10, 'MaxPayPoints Transposed'!A:A, 'MaxPayPoints Transposed'!G:G, "missing", -1)/26 -> 3440.8846 | H10: =_xlfn.XLOOKUP(A10, 'MaxPayPoints Transposed'!A:A, 'MaxPayPoints Transposed'!H:H, "missing", -1)/26 -> 4150.3462 | I10: =_xlfn.XLOOKUP(A10, 'MaxPayPoints Transposed'!A:A, 'MaxPayPoints Transposed'!I:I, "missing", -1)/26 -> 5035.1923 | J10: =_xlfn.XLOOKUP(A10, 'MaxPayPoints Transposed'!A:A, 'MaxPayPoints Transposed'!J:J, "missing", -1)/26 -> 5471.8846
A11: 43965 | B11: =_xlfn.XLOOKUP(A11, CPI!A:A, CPI!B:B, "missing",-1,1)/6.5 -> 0.061538462 | C11: =_xlfn.XLOOKUP(A11, SLCI!A:A, SLCI!B:B, "missing", -1)/6.5 -> 0.030769231 | D11: =_xlfn.XLOOKUP(A11, 'MaxPayPoints Transposed'!A:A, 'MaxPayPoints Transposed'!D:D, "missing", -1)/26 -> 2405.5 | E11: =_xlfn.XLOOKUP(A11, 'MaxPayPoints Transposed'!A:A, 'MaxPayPoints Transposed'!E:E, "missing", -1)/26 -> 2699.7692 | F11: =_xlfn.XLOOKUP(A11, 'MaxPayPoints Transposed'!A:A, 'MaxPayPoints Transposed'!F:F, "missing", -1)/26 -> 2991.1154 | G11: =_xlfn.XLOOKUP(A11, 'MaxPayPoints Transposed'!A:A, 'MaxPayPoints Transposed'!G:G, "missing", -1)/26 -> 3440.8846 | H11: =_xlfn.XLOOKUP(A11, 'MaxPayPoints Transposed'!A:A, 'MaxPayPoints Transposed'!H:H, "missing", -1)/26 -> 4150.3462 | I11: =_xlfn.XLOOKUP(A11, 'MaxPayPoints Transposed'!A:A, 'MaxPayPoints Transposed'!I:I, "missing", -1)/26 -> 5035.1923 | J11: =_xlfn.XLOOKUP(A11, 'MaxPayPoints Transposed'!A:A, 'MaxPayPoints Transposed'!J:J, "missing", -1)/26 -> 5471.8846
A12: 43979 | B12: =_xlfn.XLOOKUP(A12, CPI!A:A, CPI!B:B, "missing",-1,1)/6.5 -> 0.061538462 | C12: =_xlfn.XLOOKUP(A12, SLCI!A:A, SLCI!B:B, "missing", -1)/6.5 -> 0.030769231 | D12: =_xlfn.XLOOKUP(A12, 'MaxPayPoints Transposed'!A:A, 'MaxPayPoints Transposed'!D:D, "missing", -1)/26 -> 2405.5 | E12: =_xlfn.XLOOKUP(A12, 'MaxPayPoints Transposed'!A:A, 'MaxPayPoints Transposed'!E:E, "missing", -1)/26 -> 2699.7692 | F12: =_xlfn.XLOOKUP(A12, 'MaxPayPoints Transposed'!A:A, 'MaxPayPoints Transposed'!F:F, "missing", -1)/26 -> 2991.1154 | G12: =_xlfn.XLOOKUP(A12, 'MaxPayPoints Transposed'!A:A, 'MaxPayPoints Transposed'!G:G, "missing", -1)/26 -> 3440.8846 | H12: =_xlfn.XLOOKUP(A12, 'MaxPayPoints Transposed'!A:A, 'MaxPayPoints Transposed'!H:H, "missing", -1)/26 -> 4150.3462 | I12: =_xlfn.XLOOKUP(A12, 'MaxPayPoints Transposed'!A:A, 'MaxPayPoints Transposed'!I:I, "missing", -1)/26 -> 5035.1923 | J12: =_xlfn.XLOOKUP(A12, 'MaxPayPoints Transposed'!A:A, 'MaxPayPoints Transposed'!J:J, "missing", -1)/26 -> 5471.8846
A13: 43993 | B13: =_xlfn.XLOOKUP(A13, CPI!A:A, CPI!B:B, "missing",-1,1)/6.5 -> -0.29230769 | C13: =_xlfn.XLOOKUP(A13, SLCI!A:A, SLCI!B:B, "missing", -1)/6.5 -> -0.4 | D13: =_xlfn.XLOOKUP(A13, 'MaxPayPoints Transposed'!A:A, 'MaxPayPoints Transposed'!D:D, "missing", -1)/26 -> 2405.5 | E13: =_xlfn.XLOOKUP(A13, 'MaxPayPoints Transposed'!A:A, 'MaxPayPoints Transposed'!E:E, "missing", -1)/26 -> 2699.7692 | F13: =_xlfn.XLOOKUP(A13, 'MaxPayPoints Transposed'!A:A, 'MaxPayPoints Transposed'!F:F, "missing", -1)/26 -> 2991.1154 | G13: =_xlfn.XLOOKUP(A13, 'MaxPayPoints Transposed'!A:A, 'MaxPayPoints Transposed'!G:G, "missing", -1)/26 -> 3440.8846 | H13: =_xlfn.XLOOKUP(A13, 'MaxPayPoints Transposed'!A:A, 'MaxPayPoints Transposed'!H:H, "missing", -1)/26 -> 4150.3462 | I13: =_xlfn.XLOOKUP(A13, 'MaxPayPoints Transposed'!A:A, 'MaxPayPoints Transposed'!I:I, "missing", -1)/26 -> 5035.1923 | J13: =_xlfn.XLOOKUP(A13, 'MaxPayPoints Transposed'!A:A, 'MaxPayPoints Transposed'!J:J, "missing", -1)/26 -> 5471.8846
... A188: 46443 | B188: =_xlfn.XLOOKUP(A188, CPI!A:A, CPI!B:B, "missing",-1,1)/6.5 -> 0.092307692 | C188: =_xlfn.XLOOKUP(A188, SLCI!A:A, SLCI!B:B, "missing", -1)/6.5 -> 0.21538462 | D188: =_xlfn.XLOOKUP(A188, 'MaxPayPoints Transposed'!A:A, 'MaxPayPoints Transposed'!D:D, "missing", -1)/26 -> 2954.6154 | E188: =_xlfn.XLOOKUP(A188, 'MaxPayPoints Transposed'!A:A, 'MaxPayPoints Transposed'!E:E, "missing", -1)/26 -> 3317.1538 | F188: =_xlfn.XLOOKUP(A188, 'MaxPayPoints Transposed'!A:A, 'MaxPayPoints Transposed'!F:F, "missing", -1)/26 -> 3724.1923 | G188: =_xlfn.XLOOKUP(A188, 'MaxPayPoints Transposed'!A:A, 'MaxPayPoints Transposed'!G:G, "missing", -1)/26 -> 4296.1923 | H188: =_xlfn.XLOOKUP(A188, 'MaxPayPoints Transposed'!A:A, 'MaxPayPoints Transposed'!H:H, "missing", -1)/26 -> 5104.3462 | I188: =_xlfn.XLOOKUP(A188, 'MaxPayPoints Transposed'!A:A, 'MaxPayPoints Transposed'!I:I, "missing", -1)/26 -> 6047.8077 | J188: =_xlfn.XLOOKUP(A188, 'MaxPayPoints Transposed'!A:A, 'MaxPayPoints Transposed'!J:J, "missing", -1)/26 -> 6572.3846
